Traceback (most recent call last):
  File "d:\git space\git-demo\python study codes\try_except.py", line 192, in <module>
    1/0
ZeroDivisionError: division by zero
Traceback (most recent call last):
  File "d:\git space\git-demo\python study codes\try_except.py", line 192, in <module>
    1/0
ZeroDivisionError: division by zero
Traceback (most recent call last):
  File "d:\git space\git-demo\python study codes\try_except.py", line 192, in <module>
    1/0
ZeroDivisionError: division by zero
Traceback (most recent call last):
  File "d:\git space\git-demo\python study codes\try_except.py", line 192, in <module>
    1/0
ZeroDivisionError: division by zero
Traceback (most recent call last):
  File "d:\git space\git-demo\python study codes\try_except.py", line 192, in <module>
    1/0
ZeroDivisionError: division by zero
